============================= test session starts =============================
platform win32 -- Python 3.10.16, pytest-8.4.0, pluggy-1.6.0 -- C:\Users\JM\AppData\Local\anaconda3\envs\ENV_STONE\python.exe
cachedir: .pytest_cache
rootdir: C:\Users\JM\Documents\0_CienciaDados\1_Frameworks\Vassoura
configfile: pyproject.toml
plugins: anyio-4.9.0
collecting ... collected 9 items

vassoura/tests/test_core.py::test_search_dtypes PASSED                   [ 11%]
vassoura/tests/test_core.py::test_search_dtypes_date_col PASSED          [ 22%]
vassoura/tests/test_core.py::test_compute_corr_matrix PASSED             [ 33%]
vassoura/tests/test_core.py::test_compute_vif PASSED                     [ 44%]
vassoura/tests/test_core.py::test_clean PASSED                           [ 55%]
vassoura/tests/test_core.py::test_clean_fractional_steps PASSED          [ 66%]
vassoura/tests/test_core.py::test_missing_removal PASSED                 [ 77%]
vassoura/tests/test_core.py::test_help PASSED                            [ 88%]
vassoura/tests/test_core.py::test_iv_skipped_when_target_not_binary PASSED [100%]

============================== warnings summary ===============================
vassoura/tests/test_core.py: 24 warnings
  C:\Users\JM\Documents\0_CienciaDados\1_Frameworks\Vassoura\vassoura\utils.py:216: UserWarning: Could not infer format, so each element will be parsed individually, falling back to `dateutil`. To ensure parsing is consistent and as-expected, please specify a format.
    try_dt = pd.to_datetime(s, errors="coerce", dayfirst=True)

-- Docs: https://docs.pytest.org/en/stable/how-to/capture-warnings.html
======================= 9 passed, 24 warnings in 3.28s ========================
